<?xml version="1.0" ?>
<robot name="partnet_1676f8b995b976e5824662341ce2b233">
	<link name="base"/>
	<link name="link_0">
		<visual name="cabinet_door_surface-8">
			<origin xyz="-0.6293170790203719 -0.6086450219154358 -0.4252905637110561"/>
			<geometry>
				<mesh filename="textured_objs/original-43.obj"/>
			</geometry>
		</visual>
		<visual name="cabinet_door_surface-8">
			<origin xyz="-0.6293170790203719 -0.6086450219154358 -0.4252905637110561"/>
			<geometry>
				<mesh filename="textured_objs/original-48.obj"/>
			</geometry>
		</visual>
		<visual name="cabinet_door_surface-8">
			<origin xyz="-0.6293170790203719 -0.6086450219154358 -0.4252905637110561"/>
			<geometry>
				<mesh filename="textured_objs/original-44.obj"/>
			</geometry>
		</visual>
		<visual name="cabinet_door_surface-8">
			<origin xyz="-0.6293170790203719 -0.6086450219154358 -0.4252905637110561"/>
			<geometry>
				<mesh filename="textured_objs/original-50.obj"/>
			</geometry>
		</visual>
		<visual name="cabinet_door_surface-8">
			<origin xyz="-0.6293170790203719 -0.6086450219154358 -0.4252905637110561"/>
			<geometry>
				<mesh filename="textured_objs/original-49.obj"/>
			</geometry>
		</visual>
		<visual name="cabinet_door_surface-8">
			<origin xyz="-0.6293170790203719 -0.6086450219154358 -0.4252905637110561"/>
			<geometry>
				<mesh filename="textured_objs/original-47.obj"/>
			</geometry>
		</visual>
		<visual name="cabinet_door_surface-8">
			<origin xyz="-0.6293170790203719 -0.6086450219154358 -0.4252905637110561"/>
			<geometry>
				<mesh filename="textured_objs/original-46.obj"/>
			</geometry>
		</visual>
		<visual name="cabinet_door_surface-8">
			<origin xyz="-0.6293170790203719 -0.6086450219154358 -0.4252905637110561"/>
			<geometry>
				<mesh filename="textured_objs/original-51.obj"/>
			</geometry>
		</visual>
		<visual name="cabinet_door_surface-8">
			<origin xyz="-0.6293170790203719 -0.6086450219154358 -0.4252905637110561"/>
			<geometry>
				<mesh filename="textured_objs/original-45.obj"/>
			</geometry>
		</visual>
		<visual name="cabinet_door_surface-8">
			<origin xyz="-0.6293170790203719 -0.6086450219154358 -0.4252905637110561"/>
			<geometry>
				<mesh filename="textured_objs/original-42.obj"/>
			</geometry>
		</visual>
		<visual name="handle-9">
			<origin xyz="-0.6293170790203719 -0.6086450219154358 -0.4252905637110561"/>
			<geometry>
				<mesh filename="textured_objs/original-55.obj"/>
			</geometry>
		</visual>
		<visual name="handle-9">
			<origin xyz="-0.6293170790203719 -0.6086450219154358 -0.4252905637110561"/>
			<geometry>
				<mesh filename="textured_objs/original-53.obj"/>
			</geometry>
		</visual>
		<visual name="handle-9">
			<origin xyz="-0.6293170790203719 -0.6086450219154358 -0.4252905637110561"/>
			<geometry>
				<mesh filename="textured_objs/original-54.obj"/>
			</geometry>
		</visual>
		<collision>
			<origin xyz="-0.6293170790203719 -0.6086450219154358 -0.4252905637110561"/>
			<geometry>
				<mesh filename="textured_objs/original-43.obj"/>
			</geometry>
		</collision>
		<collision>
			<origin xyz="-0.6293170790203719 -0.6086450219154358 -0.4252905637110561"/>
			<geometry>
				<mesh filename="textured_objs/original-48.obj"/>
			</geometry>
		</collision>
		<collision>
			<origin xyz="-0.6293170790203719 -0.6086450219154358 -0.4252905637110561"/>
			<geometry>
				<mesh filename="textured_objs/original-44.obj"/>
			</geometry>
		</collision>
		<collision>
			<origin xyz="-0.6293170790203719 -0.6086450219154358 -0.4252905637110561"/>
			<geometry>
				<mesh filename="textured_objs/original-50.obj"/>
			</geometry>
		</collision>
		<collision>
			<origin xyz="-0.6293170790203719 -0.6086450219154358 -0.4252905637110561"/>
			<geometry>
				<mesh filename="textured_objs/original-49.obj"/>
			</geometry>
		</collision>
		<collision>
			<origin xyz="-0.6293170790203719 -0.6086450219154358 -0.4252905637110561"/>
			<geometry>
				<mesh filename="textured_objs/original-47.obj"/>
			</geometry>
		</collision>
		<collision>
			<origin xyz="-0.6293170790203719 -0.6086450219154358 -0.4252905637110561"/>
			<geometry>
				<mesh filename="textured_objs/original-46.obj"/>
			</geometry>
		</collision>
		<collision>
			<origin xyz="-0.6293170790203719 -0.6086450219154358 -0.4252905637110561"/>
			<geometry>
				<mesh filename="textured_objs/original-51.obj"/>
			</geometry>
		</collision>
		<collision>
			<origin xyz="-0.6293170790203719 -0.6086450219154358 -0.4252905637110561"/>
			<geometry>
				<mesh filename="textured_objs/original-45.obj"/>
			</geometry>
		</collision>
		<collision>
			<origin xyz="-0.6293170790203719 -0.6086450219154358 -0.4252905637110561"/>
			<geometry>
				<mesh filename="textured_objs/original-42.obj"/>
			</geometry>
		</collision>
		<collision>
			<origin xyz="-0.6293170790203719 -0.6086450219154358 -0.4252905637110561"/>
			<geometry>
				<mesh filename="textured_objs/original-55.obj"/>
			</geometry>
		</collision>
		<collision>
			<origin xyz="-0.6293170790203719 -0.6086450219154358 -0.4252905637110561"/>
			<geometry>
				<mesh filename="textured_objs/original-53.obj"/>
			</geometry>
		</collision>
		<collision>
			<origin xyz="-0.6293170790203719 -0.6086450219154358 -0.4252905637110561"/>
			<geometry>
				<mesh filename="textured_objs/original-54.obj"/>
			</geometry>
		</collision>
	</link>
	<joint name="joint_0" type="revolute">
		<origin xyz="0.6293170790203719 0.6086450219154358 0.4252905637110561"/>
		<axis xyz="0 0.9999999999999999 0"/>
		<child link="link_0"/>
		<parent link="link_2"/>
		<limit lower="0.0" upper="1.5707963267948966"/>
	</joint>
	<link name="link_1">
		<visual name="cabinet_door_surface-6">
			<origin xyz="0.6466144835367729 -0.6086450219154358 -0.42931528988591117"/>
			<geometry>
				<mesh filename="textured_objs/original-30.obj"/>
			</geometry>
		</visual>
		<visual name="cabinet_door_surface-6">
			<origin xyz="0.6466144835367729 -0.6086450219154358 -0.42931528988591117"/>
			<geometry>
				<mesh filename="textured_objs/original-34.obj"/>
			</geometry>
		</visual>
		<visual name="cabinet_door_surface-6">
			<origin xyz="0.6466144835367729 -0.6086450219154358 -0.42931528988591117"/>
			<geometry>
				<mesh filename="textured_objs/original-26.obj"/>
			</geometry>
		</visual>
		<visual name="cabinet_door_surface-6">
			<origin xyz="0.6466144835367729 -0.6086450219154358 -0.42931528988591117"/>
			<geometry>
				<mesh filename="textured_objs/original-32.obj"/>
			</geometry>
		</visual>
		<visual name="cabinet_door_surface-6">
			<origin xyz="0.6466144835367729 -0.6086450219154358 -0.42931528988591117"/>
			<geometry>
				<mesh filename="textured_objs/original-25.obj"/>
			</geometry>
		</visual>
		<visual name="cabinet_door_surface-6">
			<origin xyz="0.6466144835367729 -0.6086450219154358 -0.42931528988591117"/>
			<geometry>
				<mesh filename="textured_objs/original-33.obj"/>
			</geometry>
		</visual>
		<visual name="cabinet_door_surface-6">
			<origin xyz="0.6466144835367729 -0.6086450219154358 -0.42931528988591117"/>
			<geometry>
				<mesh filename="textured_objs/original-35.obj"/>
			</geometry>
		</visual>
		<visual name="cabinet_door_surface-6">
			<origin xyz="0.6466144835367729 -0.6086450219154358 -0.42931528988591117"/>
			<geometry>
				<mesh filename="textured_objs/original-27.obj"/>
			</geometry>
		</visual>
		<visual name="cabinet_door_surface-6">
			<origin xyz="0.6466144835367729 -0.6086450219154358 -0.42931528988591117"/>
			<geometry>
				<mesh filename="textured_objs/original-28.obj"/>
			</geometry>
		</visual>
		<visual name="cabinet_door_surface-6">
			<origin xyz="0.6466144835367729 -0.6086450219154358 -0.42931528988591117"/>
			<geometry>
				<mesh filename="textured_objs/original-31.obj"/>
			</geometry>
		</visual>
		<visual name="handle-7">
			<origin xyz="0.6466144835367729 -0.6086450219154358 -0.42931528988591117"/>
			<geometry>
				<mesh filename="textured_objs/original-39.obj"/>
			</geometry>
		</visual>
		<visual name="handle-7">
			<origin xyz="0.6466144835367729 -0.6086450219154358 -0.42931528988591117"/>
			<geometry>
				<mesh filename="textured_objs/original-38.obj"/>
			</geometry>
		</visual>
		<visual name="handle-7">
			<origin xyz="0.6466144835367729 -0.6086450219154358 -0.42931528988591117"/>
			<geometry>
				<mesh filename="textured_objs/original-37.obj"/>
			</geometry>
		</visual>
		<collision>
			<origin xyz="0.6466144835367729 -0.6086450219154358 -0.42931528988591117"/>
			<geometry>
				<mesh filename="textured_objs/original-30.obj"/>
			</geometry>
		</collision>
		<collision>
			<origin xyz="0.6466144835367729 -0.6086450219154358 -0.42931528988591117"/>
			<geometry>
				<mesh filename="textured_objs/original-34.obj"/>
			</geometry>
		</collision>
		<collision>
			<origin xyz="0.6466144835367729 -0.6086450219154358 -0.42931528988591117"/>
			<geometry>
				<mesh filename="textured_objs/original-26.obj"/>
			</geometry>
		</collision>
		<collision>
			<origin xyz="0.6466144835367729 -0.6086450219154358 -0.42931528988591117"/>
			<geometry>
				<mesh filename="textured_objs/original-32.obj"/>
			</geometry>
		</collision>
		<collision>
			<origin xyz="0.6466144835367729 -0.6086450219154358 -0.42931528988591117"/>
			<geometry>
				<mesh filename="textured_objs/original-25.obj"/>
			</geometry>
		</collision>
		<collision>
			<origin xyz="0.6466144835367729 -0.6086450219154358 -0.42931528988591117"/>
			<geometry>
				<mesh filename="textured_objs/original-33.obj"/>
			</geometry>
		</collision>
		<collision>
			<origin xyz="0.6466144835367729 -0.6086450219154358 -0.42931528988591117"/>
			<geometry>
				<mesh filename="textured_objs/original-35.obj"/>
			</geometry>
		</collision>
		<collision>
			<origin xyz="0.6466144835367729 -0.6086450219154358 -0.42931528988591117"/>
			<geometry>
				<mesh filename="textured_objs/original-27.obj"/>
			</geometry>
		</collision>
		<collision>
			<origin xyz="0.6466144835367729 -0.6086450219154358 -0.42931528988591117"/>
			<geometry>
				<mesh filename="textured_objs/original-28.obj"/>
			</geometry>
		</collision>
		<collision>
			<origin xyz="0.6466144835367729 -0.6086450219154358 -0.42931528988591117"/>
			<geometry>
				<mesh filename="textured_objs/original-31.obj"/>
			</geometry>
		</collision>
		<collision>
			<origin xyz="0.6466144835367729 -0.6086450219154358 -0.42931528988591117"/>
			<geometry>
				<mesh filename="textured_objs/original-39.obj"/>
			</geometry>
		</collision>
		<collision>
			<origin xyz="0.6466144835367729 -0.6086450219154358 -0.42931528988591117"/>
			<geometry>
				<mesh filename="textured_objs/original-38.obj"/>
			</geometry>
		</collision>
		<collision>
			<origin xyz="0.6466144835367729 -0.6086450219154358 -0.42931528988591117"/>
			<geometry>
				<mesh filename="textured_objs/original-37.obj"/>
			</geometry>
		</collision>
	</link>
	<joint name="joint_1" type="revolute">
		<origin xyz="-0.6466144835367729 0.6086450219154358 0.42931528988591117"/>
		<axis xyz="0 -0.9999999999999999 0"/>
		<child link="link_1"/>
		<parent link="link_2"/>
		<limit lower="-0.0" upper="1.5707963267948966"/>
	</joint>
	<link name="link_2">
		<visual name="shelf-23">
			<origin xyz="0 0 0"/>
			<geometry>
				<mesh filename="textured_objs/original-23.obj"/>
			</geometry>
		</visual>
		<visual name="shelf-24">
			<origin xyz="0 0 0"/>
			<geometry>
				<mesh filename="textured_objs/original-2.obj"/>
			</geometry>
		</visual>
		<visual name="back_panel-18">
			<origin xyz="0 0 0"/>
			<geometry>
				<mesh filename="textured_objs/original-6.obj"/>
			</geometry>
		</visual>
		<visual name="bottom_panel-19">
			<origin xyz="0 0 0"/>
			<geometry>
				<mesh filename="textured_objs/original-3.obj"/>
			</geometry>
		</visual>
		<visual name="vertical_side_panel-25">
			<origin xyz="0 0 0"/>
			<geometry>
				<mesh filename="textured_objs/original-12.obj"/>
			</geometry>
		</visual>
		<visual name="vertical_side_panel-25">
			<origin xyz="0 0 0"/>
			<geometry>
				<mesh filename="textured_objs/original-11.obj"/>
			</geometry>
		</visual>
		<visual name="vertical_side_panel-26">
			<origin xyz="0 0 0"/>
			<geometry>
				<mesh filename="textured_objs/original-16.obj"/>
			</geometry>
		</visual>
		<visual name="vertical_side_panel-26">
			<origin xyz="0 0 0"/>
			<geometry>
				<mesh filename="textured_objs/original-15.obj"/>
			</geometry>
		</visual>
		<visual name="frame_vertical_bar-27">
			<origin xyz="0 0 0"/>
			<geometry>
				<mesh filename="textured_objs/original-8.obj"/>
			</geometry>
		</visual>
		<visual name="frame_vertical_bar-28">
			<origin xyz="0 0 0"/>
			<geometry>
				<mesh filename="textured_objs/original-4.obj"/>
			</geometry>
		</visual>
		<visual name="frame_vertical_bar-29">
			<origin xyz="0 0 0"/>
			<geometry>
				<mesh filename="textured_objs/original-18.obj"/>
			</geometry>
		</visual>
		<visual name="frame_horizontal_bar-30">
			<origin xyz="0 0 0"/>
			<geometry>
				<mesh filename="textured_objs/original-22.obj"/>
			</geometry>
		</visual>
		<visual name="frame_horizontal_bar-31">
			<origin xyz="0 0 0"/>
			<geometry>
				<mesh filename="textured_objs/original-21.obj"/>
			</geometry>
		</visual>
		<visual name="frame_horizontal_bar-32">
			<origin xyz="0 0 0"/>
			<geometry>
				<mesh filename="textured_objs/original-5.obj"/>
			</geometry>
		</visual>
		<visual name="frame_horizontal_bar-33">
			<origin xyz="0 0 0"/>
			<geometry>
				<mesh filename="textured_objs/original-9.obj"/>
			</geometry>
		</visual>
		<visual name="frame_horizontal_bar-34">
			<origin xyz="0 0 0"/>
			<geometry>
				<mesh filename="textured_objs/original-7.obj"/>
			</geometry>
		</visual>
		<visual name="other_leaf-36">
			<origin xyz="0 0 0"/>
			<geometry>
				<mesh filename="textured_objs/original-56.obj"/>
			</geometry>
		</visual>
		<visual name="base_side_panel-11">
			<origin xyz="0 0 0"/>
			<geometry>
				<mesh filename="textured_objs/original-13.obj"/>
			</geometry>
		</visual>
		<visual name="base_side_panel-12">
			<origin xyz="0 0 0"/>
			<geometry>
				<mesh filename="textured_objs/original-19.obj"/>
			</geometry>
		</visual>
		<visual name="base_side_panel-13">
			<origin xyz="0 0 0"/>
			<geometry>
				<mesh filename="textured_objs/original-17.obj"/>
			</geometry>
		</visual>
		<visual name="base_side_panel-14">
			<origin xyz="0 0 0"/>
			<geometry>
				<mesh filename="textured_objs/original-20.obj"/>
			</geometry>
		</visual>
		<collision>
			<origin xyz="0 0 0"/>
			<geometry>
				<mesh filename="textured_objs/original-23.obj"/>
			</geometry>
		</collision>
		<collision>
			<origin xyz="0 0 0"/>
			<geometry>
				<mesh filename="textured_objs/original-2.obj"/>
			</geometry>
		</collision>
		<collision>
			<origin xyz="0 0 0"/>
			<geometry>
				<mesh filename="textured_objs/original-6.obj"/>
			</geometry>
		</collision>
		<collision>
			<origin xyz="0 0 0"/>
			<geometry>
				<mesh filename="textured_objs/original-3.obj"/>
			</geometry>
		</collision>
		<collision>
			<origin xyz="0 0 0"/>
			<geometry>
				<mesh filename="textured_objs/original-12.obj"/>
			</geometry>
		</collision>
		<collision>
			<origin xyz="0 0 0"/>
			<geometry>
				<mesh filename="textured_objs/original-11.obj"/>
			</geometry>
		</collision>
		<collision>
			<origin xyz="0 0 0"/>
			<geometry>
				<mesh filename="textured_objs/original-16.obj"/>
			</geometry>
		</collision>
		<collision>
			<origin xyz="0 0 0"/>
			<geometry>
				<mesh filename="textured_objs/original-15.obj"/>
			</geometry>
		</collision>
		<collision>
			<origin xyz="0 0 0"/>
			<geometry>
				<mesh filename="textured_objs/original-8.obj"/>
			</geometry>
		</collision>
		<collision>
			<origin xyz="0 0 0"/>
			<geometry>
				<mesh filename="textured_objs/original-4.obj"/>
			</geometry>
		</collision>
		<collision>
			<origin xyz="0 0 0"/>
			<geometry>
				<mesh filename="textured_objs/original-18.obj"/>
			</geometry>
		</collision>
		<collision>
			<origin xyz="0 0 0"/>
			<geometry>
				<mesh filename="textured_objs/original-22.obj"/>
			</geometry>
		</collision>
		<collision>
			<origin xyz="0 0 0"/>
			<geometry>
				<mesh filename="textured_objs/original-21.obj"/>
			</geometry>
		</collision>
		<collision>
			<origin xyz="0 0 0"/>
			<geometry>
				<mesh filename="textured_objs/original-5.obj"/>
			</geometry>
		</collision>
		<collision>
			<origin xyz="0 0 0"/>
			<geometry>
				<mesh filename="textured_objs/original-9.obj"/>
			</geometry>
		</collision>
		<collision>
			<origin xyz="0 0 0"/>
			<geometry>
				<mesh filename="textured_objs/original-7.obj"/>
			</geometry>
		</collision>
		<collision>
			<origin xyz="0 0 0"/>
			<geometry>
				<mesh filename="textured_objs/original-56.obj"/>
			</geometry>
		</collision>
		<collision>
			<origin xyz="0 0 0"/>
			<geometry>
				<mesh filename="textured_objs/original-13.obj"/>
			</geometry>
		</collision>
		<collision>
			<origin xyz="0 0 0"/>
			<geometry>
				<mesh filename="textured_objs/original-19.obj"/>
			</geometry>
		</collision>
		<collision>
			<origin xyz="0 0 0"/>
			<geometry>
				<mesh filename="textured_objs/original-17.obj"/>
			</geometry>
		</collision>
		<collision>
			<origin xyz="0 0 0"/>
			<geometry>
				<mesh filename="textured_objs/original-20.obj"/>
			</geometry>
		</collision>
	</link>
	<joint name="joint_2" type="fixed">
		<origin rpy="1.570796326794897 0 -1.570796326794897" xyz="0 0 0"/>
		<child link="link_2"/>
		<parent link="base"/>
	</joint>
</robot>
